Workbook

Sheet Arbejdsliste
A1: Screeningnr | B1: Allocation_ID | C1: Date for contact | D1: Contacted by | E1: Reason for decline | F1: Comment | G1: subjid_notdosed | H1: sbujid_dosed | I1: completed | J1: followup | K1: lost_followup
A2: 1 | B2: Lup001 | C2: 44670 | D2: MLA | H2: =B2 -> Lup001 | I2: 1 | J2: =IF(I2=1,B2,"") -> Lup001
A3: 2 | B3: Lup002 | C3: 44670 | D3: MLA | H3: =B3 -> Lup002 | I3: 0 | J3: =IF(I3=1,B3,"") | K3: Participant refused
A4: 3 | B4: Lup003 | C4: 44670 | D4: MLA | H4: =B4 -> Lup003 | I4: 1 | J4: =IF(I4=1,B4,"") -> Lup003
A5: 4 | B5: Lup009 | C5: 44676 | D5: MLA | H5: =B5 -> Lup009 | I5: 1 | J5: =IF(I5=1,B5,"") -> Lup009
A6: 5 | C6: 44676 | D6: MLA | E6: Not enough time to exercise | J6: =IF(I6=1,B6,"")
A7: 6 | B7: LUP010 | C7: 44676 | D7: MLA | H7: =B7 -> LUP010 | I7: 1 | J7: =IF(I7=1,B7,"") -> LUP010
A8: 7 | C8: 44691 | D8: MLA | E8: Not enough time to exercise | F8: Participated in another SLE study recently | J8: =IF(I8=1,B8,"")
A9: 8 | B9: LUP004 | C9: 44691 | D9: MLA | H9: =B9 -> LUP004 | I9: 1 | J9: =IF(I9=1,B9,"") -> LUP004
A10: 9 | C10: 44700 | D10: MLA | E10: Not enough time to exercise | J10: =IF(I10=1,B10,"")
A11: 10 | B11: LUP016 | C11: 44700 | D11: MLA | H11: =B11 -> LUP016 | I11: 1 | J11: =IF(I11=1,B11,"") -> LUP016
A12: 11 | C12: 44700 | D12: MLA | E12: Does not feel healthy enough to participate | F12: Broken Limb | J12: =IF(I12=1,B12,"")
A13: 12 | B13: LUP006 | C13: 44700 | D13: MLA | G13: Excluded: SLEDAI >10 | I13: 0 | J13: =IF(I13=1,B13,"")
A14: 13 | B14: LUP007 | C14: 44700 | D14: MLA | H14: =B14 -> LUP007 | I14: 1 | J14: =IF(I14=1,B14,"") -> LUP007
A15: 14 | C15: 44705 | D15: MLA | E15: No response on telephone call or email | J15: =IF(I15=1,B15,"")
A16: 15 | B16: LUP005 | C16: 44705 | D16: MLA | H16: =B16 -> LUP005 | I16: 1 | J16: =IF(I16=1,B16,"") -> LUP005
A17: 16 | B17: LUP008 | C17: 44705 | D17: MLA | H17: =B17 -> LUP008 | I17: 1 | J17: =IF(I17=1,B17,"") -> LUP008
A18: 17 | B18: LUP013 | C18: 44764 | D18: MLA | H18: =B18 -> LUP013 | I18: 1 | J18: =IF(I18=1,B18,"") -> LUP013
A19: 18 | B19: Lup011 | C19: 44784 | D19: MLA | H19: =B19 -> Lup011 | I19: 0 | J19: =IF(I19=1,B19,"") | K19: Participant refused
A20: 19 | B20: LUP012 | C20: 44788 | D20: MLA | H20: =B20 -> LUP012 | I20: 1 | J20: =IF(I20=1,B20,"") -> LUP012
A21: 20 | C21: 44797 | D21: MLA | E21: No response on telephone call or email | J21: =IF(I21=1,B21,"")
A22: 21 | D22: MLA | E22: No response on telephone call or email | J22: =IF(I22=1,B22,"")
A23: 22 | B23: LUP014 | C23: 44813 | D23: IER | H23: =B23 -> LUP014 | I23: 1 | J23: =IF(I23=1,B23,"") -> LUP014
A24: 23 | B24: LUP015 | C24: 44845 | D24: MLA | H24: =B24 -> LUP015 | I24: 1 | J24: =IF(I24=1,B24,"") -> LUP015
A25: 24 | C25: 44845 | D25: MLA | E25: Distance to study center too large | J25: =IF(I25=1,B25,"")
A26: 25 | B26: LUP021 | C26: 44845 | D26: MLA | G26: Excluded: Pregnancy | I26: 0 | J26: =IF(I26=1,B26,"") | K26: Pregnancy
A27: 26 | B27: Lup019 | C27: 44854 | D27: MLA | H27: =B27 -> Lup019 | I27: 1 | J27: =IF(I27=1,B27,"") -> Lup019
A28: 27 | C28: 44855 | D28: MLA | E28: Does not wish to participate | J28: =IF(I28=1,B28,"")
A29: 28 | C29: 44855 | D29: MLA | E29: No response on telephone call or email | J29: =IF(I29=1,B29,"")
A30: 29 | C30: 44855 | D30: MLA | E30: No response on telephone call or email | J30: =IF(I30=1,B30,"")
A31: 30 | C31: 44855 | D31: MLA | E31: No response on telephone call or email | J31: =IF(I31=1,B31,"")
A32: 31 | B32: LUP017 | C32: 44861 | D32: MLA | H32: =B32 -> LUP017 | I32: 1 | J32: =IF(I32=1,B32,"") -> LUP017
A33: 32 | D33: JL | E33: Does not feel healthy enough to participate | F33: In Fertility Treatment | J33: =IF(I33=1,B33,"")
A34: 33 | B34: LUP018 | C34: 44866 | D34: MLA | H34: =B34 -> LUP018 | I34: 1 | J34: =IF(I34=1,B34,"") -> LUP018
A35: 34 | B35: Lup028 | C35: 44903 | D35: MLA | H35: =B35 -> Lup028 | I35: 1 | J35: =IF(I35=1,B35,"") -> Lup028
A36: 35 | B36: Lup020 | C36: 44914 | D36: MLA | H36: =B36 -> Lup020 | I36: 1 | J36: =IF(I36=1,B36,"") -> Lup020
A37: 36 | B37: Lup023 | C37: 44939 | D37: MLA | H37: =B37 -> Lup023 | I37: 1 | J37: =IF(I37=1,B37,"") -> Lup023
A38: 37 | C38: 44949 | D38: MLA | E38: Not enough time to exercise | J38: =IF(I38=1,B38,"")
A39: 38 | C39: 44965 | D39: MLA | E39: No response on telephone call or email | J39: =IF(I39=1,B39,"")
A40: 39 | D40: MLA | E40: Distance to study center too large | J40: =IF(I40=1,B40,"")
...

Sheet Diagram
B1: Total | C1: Deltager Ægte | D1: Ikke deltager | H1: Det Store LUPEX Væddeløb
A2: {=_xlfn.UNIQUE(Arbejdsliste!#REF!)} -> #REF! | B2: =COUNTIF(Arbejdsliste!#REF!,Diagram!A2) -> #REF! | C2: =COUNTIFS(Arbejdsliste!#REF!,Diagram!A2,Arbejdsliste!B:B,"*lup*") -> #REF! | D2: =B2-C2 -> #REF! | T2: Ja
B3: =COUNTIF(Arbejdsliste!#REF!,Diagram!A3) -> #REF! | C3: =COUNTIFS(Arbejdsliste!#REF!,Diagram!A3,Arbejdsliste!B:B,"*lup*") -> #REF! | D3: =B3-C3 -> #REF!
B4: =COUNTIF(Arbejdsliste!#REF!,Diagram!A4) -> #REF! | C4: =COUNTIFS(Arbejdsliste!#REF!,Diagram!A4,Arbejdsliste!B:B,"*lup*") -> #REF! | D4: =B4-C4 -> #REF!
B5: =COUNTIF(Arbejdsliste!#REF!,Diagram!A5) -> #REF! | C5: =COUNTIFS(Arbejdsliste!#REF!,Diagram!A5,Arbejdsliste!B:B,"*lup*") -> #REF! | D5: =B5-C5 -> #REF!
B6: =COUNTIF(Arbejdsliste!#REF!,Diagram!A6) -> #REF! | C6: =COUNTIFS(Arbejdsliste!#REF!,Diagram!A6,Arbejdsliste!B:B,"*lup*") -> #REF! | D6: =B6-C6 -> #REF!
B7: =COUNTIF(Arbejdsliste!#REF!,Diagram!A7) -> #REF! | C7: =COUNTIFS(Arbejdsliste!#REF!,Diagram!A7,Arbejdsliste!B:B,"*lup*") -> #REF! | D7: =B7-C7 -> #REF!
B8: =COUNTIF(Arbejdsliste!#REF!,Diagram!A8) -> #REF! | C8: =COUNTIFS(Arbejdsliste!#REF!,Diagram!A8,Arbejdsliste!B:B,"*lup*") -> #REF! | D8: =B8-C8 -> #REF!
B9: =COUNTIF(Arbejdsliste!#REF!,Diagram!A9) -> #REF! | C9: =COUNTIFS(Arbejdsliste!#REF!,Diagram!A9,Arbejdsliste!B:B,"*lup*") -> #REF! | D9: =B9-C9 -> #REF!
B10: =COUNTIF(Arbejdsliste!#REF!,Diagram!A10) -> #REF! | C10: =COUNTIFS(Arbejdsliste!#REF!,Diagram!A10,Arbejdsliste!B:B,"*lup*") -> #REF! | D10: =B10-C10 -> #REF!
B11: =COUNTIF(Arbejdsliste!#REF!,Diagram!A11) -> #REF! | C11: =COUNTIFS(Arbejdsliste!#REF!,Diagram!A11,Arbejdsliste!B:B,"*lup*") -> #REF! | D11: =B11-C11 -> #REF!
B12: =COUNTIF(Arbejdsliste!#REF!,Diagram!A12) -> #REF! | C12: =COUNTIFS(Arbejdsliste!#REF!,Diagram!A12,Arbejdsliste!B:B,"*lup*") -> #REF! | D12: =B12-C12 -> #REF!
B13: =COUNTIF(Arbejdsliste!#REF!,Diagram!A13) -> #REF! | C13: =COUNTIFS(Arbejdsliste!#REF!,Diagram!A13,Arbejdsliste!B:B,"*lup*") -> #REF! | D13: =B13-C13 -> #REF!
B14: =COUNTIF(Arbejdsliste!#REF!,Diagram!A14) -> #REF! | C14: =COUNTIFS(Arbejdsliste!#REF!,Diagram!A14,Arbejdsliste!B:B,"*lup*") -> #REF! | D14: =B14-C14 -> #REF!
... B18: =COUNTIF(Arbejdsliste!#REF!,Diagram!A18) -> #REF! | C18: =COUNTIFS(Arbejdsliste!#REF!,Diagram!A18,Arbejdsliste!B:B,"*lup*") -> #REF! | D18: =B18-C18 -> #REF!
B19: =COUNTIF(Arbejdsliste!#REF!,Diagram!A19) -> #REF! | C19: =COUNTIFS(Arbejdsliste!#REF!,Diagram!A19,Arbejdsliste!#REF!,$T$2) -> #REF! | D19: =B19-C19 -> #REF!
C20: =SUM(C2:C19) -> #REF!

Sheet StudieInfo
A1: H-21039032 | C1: April 5, 2022
A2: Lupex Protokol - Type 1 interferon induced changes to exercise adaptations in systemic lupus erythematosus patients
A5: Aktuelt i Studiet | B5: =COUNTIFS(Arbejdsliste!#REF!,TODAY(),Arbejdsliste!#REF!,TODAY()) -> #REF!
